Workbook

Sheet village-reports
B1: =_xludf.textjoin("",TRUE,"Panchayat Report: ",J4,", ",G4, " Mandal") -> #NAME? | S1: Assembly | T1: Mandal | U1: Panchayat | W1: Year | X1: TDP | Y1: YSRCP | Z1: JSP
S2: Tuni | T2: =IFERROR(__xludf.DUMMYFUNCTION("unique(filter('Back End'!B:B,'Back End'!A:A=D4))"),"Prathipadu") -> Prathipadu | U2: =IFERROR(__xludf.DUMMYFUNCTION("unique(filter('Back End'!C:C,'Back End'!A:A=D4,'Back End'!B:B=G4))"),"Bavuruvaka") -> Bavuruvaka | W2: 2024 | X2: =C24 -> #N/A | Y2: =D24 -> 0 | Z2: =E24 -> 0
S3: Prathipadu | T3: =IFERROR(__xludf.DUMMYFUNCTION("""COMPUTED_VALUE"""),"Rowthulapudi") -> Rowthulapudi | U3: =IFERROR(__xludf.DUMMYFUNCTION("""COMPUTED_VALUE"""),"Buradakota") -> Buradakota | W3: 2019 | X3: =C26 -> 0.54149378 | Y3: =D26 -> 0.34439834 | Z3: =E26 -> 0.010373444
C4: Assembly | D4: Prathipadu | F4: Mandal | G4: Prathipadu | I4: Panchayat | J4: Buradakota | S4: Pithapuram | T4: =IFERROR(__xludf.DUMMYFUNCTION("""COMPUTED_VALUE"""),"Sankhavaram") -> Sankhavaram | U4: =IFERROR(__xludf.DUMMYFUNCTION("""COMPUTED_VALUE"""),"Chinasankarlapudi") -> Chinasankarlapudi | W4: 2014 | X4: =C28 -> 0.44239631 | Y4: =D28 -> 0.099078341 | Z4: =E28 -> 0
S5: Kakinada Rural | T5: =IFERROR(__xludf.DUMMYFUNCTION("""COMPUTED_VALUE"""),"Yeleswaram") -> Yeleswaram | U5: =IFERROR(__xludf.DUMMYFUNCTION("""COMPUTED_VALUE"""),"Chintaluru") -> Chintaluru
B6: Current Sarpanch | D6: =IFERROR(__xludf.DUMMYFUNCTION("filter(Data!F:F,Data!C:C=G4,Data!D:D=J4)"),"Chinthala Chinnalamma - 9493461257") -> Chinthala Chinnalamma - 9493461257 | F6: Party | H6: =IFERROR(__xludf.DUMMYFUNCTION("filter(Data!G:G,Data!C:C=G4,Data!D:D=J4)"),"") | J6: TDP - Current Position | L6: =IFERROR(__xludf.DUMMYFUNCTION("filter(Data!H:H,Data!C:C=G4,Data!D:D=J4)"),"") | S6: Peddapuram | T6: =IFERROR(__xludf.DUMMYFUNCTION("""COMPUTED_VALUE"""),"Yeleswaram Town") -> Yeleswaram Town | U6: =IFERROR(__xludf.DUMMYFUNCTION("""COMPUTED_VALUE"""),"Dharmavaram") -> Dharmavaram
S7: Kakinada Urban | U7: =IFERROR(__xludf.DUMMYFUNCTION("""COMPUTED_VALUE"""),"Gajjanapudi") -> Gajjanapudi
B8: Demographics | H8: Prominent Castes | S8: Jaggampeta | U8: =IFERROR(__xludf.DUMMYFUNCTION("""COMPUTED_VALUE"""),"Gokavaram") -> Gokavaram
U9: =IFERROR(__xludf.DUMMYFUNCTION("""COMPUTED_VALUE"""),"Lampakalova") -> Lampakalova
B10: =_xludf.textjoin("",TRUE,"Age Wise Electors",CHAR(10),"Total: ",D16+F16) -> #NAME? | H10: S No. | I10: Caste | K10: Voters | L10: Inclination | U10: =IFERROR(__xludf.DUMMYFUNCTION("""COMPUTED_VALUE"""),"Pandavulapalem") -> Pandavulapalem
B11: Age | D11: Male | F11: Female | H11: 1 | I11: =IFERROR(__xludf.DUMMYFUNCTION("filter('Caste Data'!D:D,'Caste Data'!A:A=D$4,'Caste Data'!B:B=G$4,'Caste Data'!C:C=J$4,'Caste Data'!G:G=H11)"),"Valmiki") -> Valmiki | K11: =IFERROR(__xludf.DUMMYFUNCTION("filter('Caste Data'!F:F,'Caste Data'!A:A=D$4,'Caste Data'!B:B=G$4,'Caste Data'!C:C=J$4,'Caste Data'!G:G=H11)"),259) -> 259 | U11: =IFERROR(__xludf.DUMMYFUNCTION("""COMPUTED_VALUE"""),"Peda Sankarlapudi") -> Peda Sankarlapudi
B12: 18-24 | D12: =IFERROR(__xludf.DUMMYFUNCTION("transpose(filter({Demography!S2:V1014,Demography!L2:L1014},Demography!A2:A1014=D4,Demography!B2:B1014=G4,Demography!D2:D1014=J4))"),33) -> 33 | F12: =IFERROR(__xludf.DUMMYFUNCTION("transpose(filter({Demography!O2:R1014, Demography!M2:M1014},Demography!A2:A1014=D4,Demography!B2:B1014=G4,Demography!D2:D1014=J4))"),20) -> 20 | H12: 2 | I12: =IFERROR(__xludf.DUMMYFUNCTION("filter('Caste Data'!D:D,'Caste Data'!A:A=D$4,'Caste Data'!B:B=G$4,'Caste Data'!C:C=J$4,'Caste Data'!G:G=H12)"),"K.Kapu") -> K.Kapu | K12: =IFERROR(__xludf.DUMMYFUNCTION("filter('Caste Data'!F:F,'Caste Data'!A:A=D$4,'Caste Data'!B:B=G$4,'Caste Data'!C:C=J$4,'Caste Data'!G:G=H12)"),257) -> 257 | U12: =IFERROR(__xludf.DUMMYFUNCTION("""COMPUTED_VALUE"""),"Peddipalem") -> Peddipalem
B13: 25-44 | D13: =IFERROR(__xludf.DUMMYFUNCTION("""COMPUTED_VALUE"""),155) -> 155 | F13: =IFERROR(__xludf.DUMMYFUNCTION("""COMPUTED_VALUE"""),165) -> 165 | H13: 3 | I13: =IFERROR(__xludf.DUMMYFUNCTION("filter('Caste Data'!D:D,'Caste Data'!A:A=D$4,'Caste Data'!B:B=G$4,'Caste Data'!C:C=J$4,'Caste Data'!G:G=H13)"),"K.Dora") -> K.Dora | K13: =IFERROR(__xludf.DUMMYFUNCTION("filter('Caste Data'!F:F,'Caste Data'!A:A=D$4,'Caste Data'!B:B=G$4,'Caste Data'!C:C=J$4,'Caste Data'!G:G=H13)"),200) -> 200 | U13: =IFERROR(__xludf.DUMMYFUNCTION("""COMPUTED_VALUE"""),"Pothuluru") -> Pothuluru
B14: 45-59 | D14: =IFERROR(__xludf.DUMMYFUNCTION("""COMPUTED_VALUE"""),55) -> 55 | F14: =IFERROR(__xludf.DUMMYFUNCTION("""COMPUTED_VALUE"""),75) -> 75 | H14: 4 | I14: =IFERROR(__xludf.DUMMYFUNCTION("filter('Caste Data'!D:D,'Caste Data'!A:A=D$4,'Caste Data'!B:B=G$4,'Caste Data'!C:C=J$4,'Caste Data'!G:G=H14)"),"Kapu") -> Kapu | K14: =IFERROR(__xludf.DUMMYFUNCTION("filter('Caste Data'!F:F,'Caste Data'!A:A=D$4,'Caste Data'!B:B=G$4,'Caste Data'!C:C=J$4,'Caste Data'!G:G=H14)"),10) -> 10 | U14: =IFERROR(__xludf.DUMMYFUNCTION("""COMPUTED_VALUE"""),"Prathipadu") -> Prathipadu
B15: 60+ | D15: =IFERROR(__xludf.DUMMYFUNCTION("""COMPUTED_VALUE"""),25) -> 25 | F15: =IFERROR(__xludf.DUMMYFUNCTION("""COMPUTED_VALUE"""),29) -> 29 | H15: 5 | I15: =IFERROR(__xludf.DUMMYFUNCTION("filter('Caste Data'!D:D,'Caste Data'!A:A=D$4,'Caste Data'!B:B=G$4,'Caste Data'!C:C=J$4,'Caste Data'!G:G=H15)"),"Yadava") -> Yadava | K15: =IFERROR(__xludf.DUMMYFUNCTION("filter('Caste Data'!F:F,'Caste Data'!A:A=D$4,'Caste Data'!B:B=G$4,'Caste Data'!C:C=J$4,'Caste Data'!G:G=H15)"),6) -> 6 | U15: =IFERROR(__xludf.DUMMYFUNCTION("""COMPUTED_VALUE"""),"Rachapalle") -> Rachapalle
B16: Total | D16: =IFERROR(__xludf.DUMMYFUNCTION("""COMPUTED_VALUE"""),268) -> 268 | F16: =IFERROR(__xludf.DUMMYFUNCTION("""COMPUTED_VALUE"""),289) -> 289 | H16: 6 | I16: =IFERROR(__xludf.DUMMYFUNCTION("filter('Caste Data'!D:D,'Caste Data'!A:A=D$4,'Caste Data'!B:B=G$4,'Caste Data'!C:C=J$4,'Caste Data'!G:G=H16)"),"Others BCs") -> Others BCs | K16: =IFERROR(__xludf.DUMMYFUNCTION("filter('Caste Data'!F:F,'Caste Data'!A:A=D$4,'Caste Data'!B:B=G$4,'Caste Data'!C:C=J$4,'Caste Data'!G:G=H16)"),4) -> 4 | U16: =IFERROR(__xludf.DUMMYFUNCTION("""COMPUTED_VALUE"""),"Rowthulapalem") -> Rowthulapalem
B17: Cohort Groups | D17: =IFERROR(__xludf.DUMMYFUNCTION("filter('Raw Data - Field Input'!H2:H1014,'Raw Data - Field Input'!A2:A1014=D4,'Raw Data - Field Input'!B2:B1014=G4,'Raw Data - Field Input'!D2:D1014=J4)"),"1.paddy farming 2.cashew farming") -> 1.paddy farming 2.cashew farming | H17: 7 | I17: =IFERROR(__xludf.DUMMYFUNCTION("filter('Caste Data'!D:D,'Caste Data'!A:A=D$4,'Caste Data'!B:B=G$4,'Caste Data'!C:C=J$4,'Caste Data'!G:G=H17)"),"Others OCs") -> Others OCs | K17: =IFERROR(__xludf.DUMMYFUNCTION("filter('Caste Data'!F:F,'Caste Data'!A:A=D$4,'Caste Data'!B:B=G$4,'Caste Data'!C:C=J$4,'Caste Data'!G:G=H17)"),4) -> 4 | U17: =IFERROR(__xludf.DUMMYFUNCTION("""COMPUTED_VALUE"""),"Sarabhavaram") -> Sarabhavaram
H18: 8 | I18: =IFERROR(__xludf.DUMMYFUNCTION("filter('Caste Data'!D:D,'Caste Data'!A:A=D$4,'Caste Data'!B:B=G$4,'Caste Data'!C:C=J$4,'Caste Data'!G:G=H18)"),"#N/A") -> #N/A | K18: =IFERROR(__xludf.DUMMYFUNCTION("filter('Caste Data'!F:F,'Caste Data'!A:A=D$4,'Caste Data'!B:B=G$4,'Caste Data'!C:C=J$4,'Caste Data'!G:G=H18)"),"#N/A") -> #N/A | U18: =IFERROR(__xludf.DUMMYFUNCTION("""COMPUTED_VALUE"""),"T Rayavaram") -> T Rayavaram
H19: 9 | I19: =IFERROR(__xludf.DUMMYFUNCTION("filter('Caste Data'!D:D,'Caste Data'!A:A=D$4,'Caste Data'!B:B=G$4,'Caste Data'!C:C=J$4,'Caste Data'!G:G=H19)"),"#N/A") -> #N/A | K19: =IFERROR(__xludf.DUMMYFUNCTION("filter('Caste Data'!F:F,'Caste Data'!A:A=D$4,'Caste Data'!B:B=G$4,'Caste Data'!C:C=J$4,'Caste Data'!G:G=H19)"),"#N/A") -> #N/A | U19: =IFERROR(__xludf.DUMMYFUNCTION("""COMPUTED_VALUE"""),"U.Jagannadhapuram") -> U.Jagannadhapuram
H20: 10 | I20: =IFERROR(__xludf.DUMMYFUNCTION("filter('Caste Data'!D:D,'Caste Data'!A:A=D$4,'Caste Data'!B:B=G$4,'Caste Data'!C:C=J$4,'Caste Data'!G:G=H20)"),"#N/A") -> #N/A | K20: =IFERROR(__xludf.DUMMYFUNCTION("filter('Caste Data'!F:F,'Caste Data'!A:A=D$4,'Caste Data'!B:B=G$4,'Caste Data'!C:C=J$4,'Caste Data'!G:G=H20)"),"#N/A") -> #N/A | U20: =IFERROR(__xludf.DUMMYFUNCTION("""COMPUTED_VALUE"""),"Uttarakanchi") -> Uttarakanchi
B21: Retro | U21: =IFERROR(__xludf.DUMMYFUNCTION("""COMPUTED_VALUE"""),"Vakapalle") -> Vakapalle
U22: =IFERROR(__xludf.DUMMYFUNCTION("""COMPUTED_VALUE"""),"Venkatanagaram") -> Venkatanagaram
B23: Election | C23: TDP | D23: YSRCP | E23: JSP | F23: BJP | G23: INC | H23: PRP | I23: Others | J23: AE Results | U23: =IFERROR(__xludf.DUMMYFUNCTION("""COMPUTED_VALUE"""),"Vommangi") -> Vommangi
B24: 2024 AE | C24: =IFERROR(__xludf.DUMMYFUNCTION("filter('Village-F20-2024'!W:AC,'Village-F20-2024'!D:D=D$4,'Village-F20-2024'!E:E=G$4,'Village-F20-2024'!F:F=J$4)"),"#N/A") -> #N/A | U24: =IFERROR(__xludf.DUMMYFUNCTION("""COMPUTED_VALUE"""),"Yeluru") -> Yeluru
B25: 2024 PE
B26: 2019 AE | C26: =IFERROR(__xludf.DUMMYFUNCTION("filter('Retro Villagewise'!L2:R1014,'Retro Villagewise'!A2:A1014=D4,'Retro Villagewise'!B2:B1014=G4,'Retro Villagewise'!D2:D1014=J4)"),0.5414937759) -> 0.54149378 | D26: =IFERROR(__xludf.DUMMYFUNCTION("""COMPUTED_VALUE"""),0.3443983402) -> 0.34439834 | E26: =IFERROR(__xludf.DUMMYFUNCTION("""COMPUTED_VALUE"""),0.01037344398) -> 0.010373444 | F26: =IFERROR(__xludf.DUMMYFUNCTION("""COMPUTED_VALUE"""),0) -> 0 | G26: =IFERROR(__xludf.DUMMYFUNCTION("""COMPUTED_VALUE"""),0) -> 0 | H26: =IFERROR(__xludf.DUMMYFUNCTION("""COMPUTED_VALUE"""),0) -> 0 | I26: =IFERROR(__xludf.DUMMYFUNCTION("""COMPUTED_VALUE"""),0.1037344398) -> 0.10373444
B27: 2019 PE | C27: =IFERROR(__xludf.DUMMYFUNCTION("filter('Retro Villagewise'!E2:K1014,'Retro Villagewise'!A2:A1014=D4,'Retro Villagewise'!B2:B1014=G4,'Retro Villagewise'!D2:D1014=J4)"),0.7697095436) -> 0.76970954 | D27: =IFERROR(__xludf.DUMMYFUNCTION("""COMPUTED_VALUE"""),0.1095435685) -> 0.10954357 | E27: =IFERROR(__xludf.DUMMYFUNCTION("""COMPUTED_VALUE"""),0.01244813278) -> 0.012448133 | F27: =IFERROR(__xludf.DUMMYFUNCTION("""COMPUTED_VALUE"""),0.01659751037) -> 0.01659751 | G27: =IFERROR(__xludf.DUMMYFUNCTION("""COMPUTED_VALUE"""),0) -> 0 | H27: =IFERROR(__xludf.DUMMYFUNCTION("""COMPUTED_VALUE"""),0) -> 0 | I27: =IFERROR(__xludf.DUMMYFUNCTION("""COMPUTED_VALUE"""),0.8941908714) -> 0.89419087
B28: 2014 AE | C28: =IFERROR(__xludf.DUMMYFUNCTION("filter('Retro Villagewise'!Z2:AF1014,'Retro Villagewise'!A2:A1014=D4,'Retro Villagewise'!B2:B1014=G4,'Retro Villagewise'!D2:D1014=J4)"),0.4423963134) -> 0.44239631 | D28: =IFERROR(__xludf.DUMMYFUNCTION("""COMPUTED_VALUE"""),0.09907834101) -> 0.099078341 | E28: =IFERROR(__xludf.DUMMYFUNCTION("""COMPUTED_VALUE"""),0) -> 0 | F28: =IFERROR(__xludf.DUMMYFUNCTION("""COMPUTED_VALUE"""),0) -> 0 | G28: =IFERROR(__xludf.DUMMYFUNCTION("""COMPUTED_VALUE"""),0.05529953917) -> 0.055299539 | H28: =IFERROR(__xludf.DUMMYFUNCTION("""COMPUTED_VALUE"""),0) -> 0 | I28: =IFERROR(__xludf.DUMMYFUNCTION("""COMPUTED_VALUE"""),0.4032258065) -> 0.40322581
B29: 2014 PE | C29: =IFERROR(__xludf.DUMMYFUNCTION("filter('Retro Villagewise'!S2:Y1014,'Retro Villagewise'!A2:A1014=D4,'Retro Villagewise'!B2:B1014=G4,'Retro Villagewise'!D2:D1014=J4)"),0.4907834101) -> 0.49078341 | D29: =IFERROR(__xludf.DUMMYFUNCTION("""COMPUTED_VALUE"""),0.09447004608) -> 0.094470046 | E29: =IFERROR(__xludf.DUMMYFUNCTION("""COMPUTED_VALUE"""),0) -> 0 | F29: =IFERROR(__xludf.DUMMYFUNCTION("""COMPUTED_VALUE"""),0) -> 0 | G29: =IFERROR(__xludf.DUMMYFUNCTION("""COMPUTED_VALUE"""),0.01382488479) -> 0.013824885 | H29: =IFERROR(__xludf.DUMMYFUNCTION("""COMPUTED_VALUE"""),0) -> 0 | I29: =IFERROR(__xludf.DUMMYFUNCTION("""COMPUTED_VALUE"""),0.400921659) -> 0.40092166
B30: 2009 AE | C30: =IFERROR(__xludf.DUMMYFUNCTION("filter('Retro Villagewise'!AN2:AT1014,'Retro Villagewise'!A2:A1014=D4,'Retro Villagewise'!B2:B1014=G4,'Retro Villagewise'!D2:D1014=J4)"),0.4293478261) -> 0.42934783 | D30: =IFERROR(__xludf.DUMMYFUNCTION("""COMPUTED_VALUE"""),0) -> 0 | E30: =IFERROR(__xludf.DUMMYFUNCTION("""COMPUTED_VALUE"""),0) -> 0 | F30: =IFERROR(__xludf.DUMMYFUNCTION("""COMPUTED_VALUE"""),0) -> 0 | G30: =IFERROR(__xludf.DUMMYFUNCTION("""COMPUTED_VALUE"""),0.1086956522) -> 0.10869565 | H30: =IFERROR(__xludf.DUMMYFUNCTION("""COMPUTED_VALUE"""),0.2092391304) -> 0.20923913 | I30: =IFERROR(__xludf.DUMMYFUNCTION("""COMPUTED_VALUE"""),0.2527173913) -> 0.25271739
B31: 2009 PE | C31: =IFERROR(__xludf.DUMMYFUNCTION("filter('Retro Villagewise'!AG2:AM1014,'Retro Villagewise'!A2:A1014=D4,'Retro Villagewise'!B2:B1014=G4,'Retro Villagewise'!D2:D1014=J4)"),0.4048913043) -> 0.4048913 | D31: =IFERROR(__xludf.DUMMYFUNCTION("""COMPUTED_VALUE"""),0) -> 0 | E31: =IFERROR(__xludf.DUMMYFUNCTION("""COMPUTED_VALUE"""),0) -> 0 | F31: =IFERROR(__xludf.DUMMYFUNCTION("""COMPUTED_VALUE"""),0.01630434783) -> 0.016304348 | G31: =IFERROR(__xludf.DUMMYFUNCTION("""COMPUTED_VALUE"""),0.08967391304) -> 0.089673913 | H31: =IFERROR(__xludf.DUMMYFUNCTION("""COMPUTED_VALUE"""),0.2255434783) -> 0.22554348 | I31: =IFERROR(__xludf.DUMMYFUNCTION("""COMPUTED_VALUE"""),0.2635869565) -> 0.26358696
B32: 2024 AE Story | H32: 2019 AE Story
B33: =IFERROR(__xludf.DUMMYFUNCTION("filter(Data!I:I,Data!C:C=G4,Data!D:D=J4)"),"") | H33: =IFERROR(__xludf.DUMMYFUNCTION("filter('Raw Data - Field Input'!J2:J1014,'Raw Data - Field Input'!A2:A1014=D4,'Raw Data - Field Input'!B2:B1014=G4,'Raw Data - Field Input'!D2:D1014=J4)"),"1. This is ST Konda dora dominant village which is majorly inclined towards YCP party . 2.TDP banked on Kapu along with Bc community of settibalija. 3.TDP failed to fulfil the promises of laying roads and hence there is a shift of vote bank towards YCP pa"&"rty to give it a one chance.") -> 1. This is ST Konda dora dominant village which is majorly inclined towards YCP party . 2.TDP banked on Kapu along with Bc community of settibalija. 3.TDP failed to fulfil the promises of laying roads and hence there is a shift of vote bank towards YCP party to give it a one chance.
B40: Sarpanch Election Scenario
B42: 2020 Election Scenario | H42: Expected Contestants for 2026 Elections
B43: =IFERROR(__xludf.DUMMYFUNCTION("filter(Data!J:J,Data!C:C=G4,Data!D:D=J4)"),"") | H43: Possible Reservation | K43: =IFERROR(__xludf.DUMMYFUNCTION("filter(Data!K:K,Data!C:C=G4,Data!D:D=J4)"),"")
H44: =IFERROR(__xludf.DUMMYFUNCTION("filter(Data!L:L,Data!C:C=G4,Data!D:D=J4)"),"")
B48: Key Leaders
B50: S No | C50: Name | F50: Caste | H50: Category | I50: Party | J50: Designation | L50: Mobile | M50: Influence
B51: 1 | C51: =IFERROR(__xludf.DUMMYFUNCTION("filter('Key Leaders'!E:E,'Key Leaders'!D:D=B51,'Key Leaders'!A:A=D$4,'Key Leaders'!B:B=G$4,'Key Leaders'!C:C=J$4)"),"#N/A") -> #N/A | F51: =IFERROR(__xludf.DUMMYFUNCTION("filter('Key Leaders'!F:F,'Key Leaders'!D:D=B51,'Key Leaders'!A:A=D$4,'Key Leaders'!B:B=G$4,'Key Leaders'!C:C=J$4)"),"#N/A") -> #N/A | H51: =IFERROR(__xludf.DUMMYFUNCTION("filter('Key Leaders'!G:H,'Key Leaders'!D:D=B51,'Key Leaders'!A:A=D$4,'Key Leaders'!B:B=G$4,'Key Leaders'!C:C=J$4)"),"#N/A") -> #N/A | J51: =IFERROR(__xludf.DUMMYFUNCTION("filter('Key Leaders'!I:I,'Key Leaders'!D:D=B51,'Key Leaders'!A:A=D$4,'Key Leaders'!B:B=G$4,'Key Leaders'!C:C=J$4)"),"#N/A") -> #N/A | L51: =IFERROR(__xludf.DUMMYFUNCTION("filter('Key Leaders'!J:K,'Key Leaders'!D:D=B51,'Key Leaders'!A:A=D$4,'Key Leaders'!B:B=G$4,'Key Leaders'!C:C=J$4)"),"#N/A") -> #N/A
...

Sheet Demography
A1: Assembly | B1: Mandal | D1: Village | E1: Categorisation PE | F1: Total PSs | G1: Sarpanch Name | H1: Sarpanch Party | I1: Reservation | J1: Sarpanch Caste | K1: Sarpanch Mobile No | L1: Male Voters | M1: Female Voters | N1: Total Voters | O1: 18-24 (F) Voters | P1: 25-44 (F) Voters | Q1: 45-59 (F) Voters | R1: 60+ (F) Voters | S1: 18-24 (M) Voters | T1: 25-44 (M) Voters | U1: 45-59 (M) Voters | V1: 60+ (M) Voters | W1: 18-24 | X1: 25-44 | Y1: 45-59 | Z1: 60+ | AA1: SC | AB1: ST | AC1: >50K Benf HH
A2: Jaggampeta | B2: Gandepalle | C2: Borrampalem | D2: Borrampalem | E2: Battleground | F2: 1 | G2: Pokala Subbarao | H2: YCP | I2: UR(G) | J2: Perika | K2: 9705171931 | L2: 515 | M2: 502 | N2: 1017 | O2: 49 | P2: 205 | Q2: 160 | R2: 87 | S2: 57 | T2: 257 | U2: 125 | V2: 76 | AC2: 67
A3: Jaggampeta | B3: Gandepalle | C3: Gandepalle | D3: Gandepalle | E3: Favourable | F3: 2 | G3: Rutthala Lalitha Devi | H3: YCP | I3: BC(W) | J3: Velama | K3: 6300566579 | L3: 1096 | M3: 1114 | N3: 2211 | O3: 59 | P3: 433 | Q3: 380 | R3: 242 | S3: 70 | T3: 422 | U3: 329 | V3: 275 | AC3: 61
A4: Jaggampeta | B4: Gandepalle | C4: K. Nayakampalle | D4: K. Nayakampalle | E4: Safe | F4: 1 | G4: Mallireddy Mahalakshmi Varahalu | H4: YCP | I4: UR(W) | J4: Kamma | K4: 9441246682 | L4: 402 | M4: 415 | N4: 817 | O4: 29 | P4: 179 | Q4: 114 | R4: 93 | S4: 24 | T4: 193 | U4: 104 | V4: 81 | AC4: 66
A5: Jaggampeta | B5: Gandepalle | C5: K.Gopalapuram | D5: K.Gopalapuram | E5: Battleground | F5: 6 | G5: Karri Suryakantham | H5: OTHERS | I5: UR(W) | J5: T.Kapu | K5: 9502562392 | L5: 2900 | M5: 2950 | N5: 5854 | O5: 164 | P5: 1374 | Q5: 827 | R5: 585 | S5: 231 | T5: 1480 | U5: 713 | V5: 475 | AC5: 83
A6: Jaggampeta | B6: Gandepalle | C6: Mallepalli | D6: Mallepalli | E6: Battleground | F6: 4 | G6: Ballireddy Varalakshmi | H6: YCP | I6: BC(W) | J6: T.Kapu | K6: 9493839571 | L6: 2006 | M6: 1951 | N6: 3957 | O6: 110 | P6: 913 | Q6: 514 | R6: 412 | S6: 138 | T6: 1063 | U6: 459 | V6: 346 | AC6: 83
A7: Jaggampeta | B7: Gandepalle | C7: Mallepalli | D7: Pathuru | E7: Battleground | F7: 1 | G7: Ballireddy Varalakshmi | H7: YCP | I7: BC(W) | J7: T.Kapu | K7: 9493839571 | L7: 470 | M7: 513 | N7: 983 | O7: 21 | P7: 223 | Q7: 152 | R7: 117 | S7: 23 | T7: 252 | U7: 124 | V7: 71 | AC7: 83
A8: Jaggampeta | B8: Gandepalle | C8: Murari | D8: Murari | E8: Favourable | F8: 3 | G8: Kukkala Ananda Babu | H8: OTHERS | I8: SC(G) | J8: Mala | K8: 9949147450 | L8: 1659 | M8: 1732 | N8: 3392 | O8: 95 | P8: 831 | Q8: 453 | R8: 352 | S8: 124 | T8: 829 | U8: 422 | V8: 283 | AC8: 62
A9: Jaggampeta | B9: Gandepalle | C9: N.T.Rajapuram | D9: N.T.Rajapuram | E9: Battleground | F9: 2 | G9: Bikkina Devi Durga | H9: YCP | I9: UR(W) | J9: Kamma | K9: 8309596673 | L9: 718 | M9: 765 | N9: 1484 | O9: 44 | P9: 375 | Q9: 225 | R9: 121 | S9: 59 | T9: 373 | U9: 176 | V9: 110 | AC9: 90
A10: Jaggampeta | B10: Gandepalle | C10: Neeladriraopeta | D10: Neeladriraopeta | E10: Battleground | F10: 5 | G10: Mulampaka Suresh Babu | H10: YCP | I10: BC(G) | J10: Kummari | K10: 9059315666 | L10: 2396 | M10: 2407 | N10: 4804 | O10: 152 | P10: 1134 | Q10: 702 | R10: 417 | S10: 205 | T10: 1248 | U10: 586 | V10: 357 | AC10: 87
A11: Jaggampeta | B11: Gandepalle | C11: P. Nayakampalle | D11: P. Nayakampalle | E11: Battleground | F11: 2 | G11: Mallireddy Annapurna | H11: YCP | I11: UR(W) | J11: Kamma | K11: 9692879999 | L11: 871 | M11: 876 | N11: 1749 | O11: 53 | P11: 422 | Q11: 217 | R11: 183 | S11: 58 | T11: 417 | U11: 240 | V11: 156 | AC11: 66
A12: Jaggampeta | B12: Gandepalle | C12: P.Surampalem | D12: P.Surampalem | E12: Battleground | F12: 2 | G12: Marisetti Gangabhavani | H12: YCP | I12: BC(W) | J12: Setti Balija | K12: 8897945154 | L12: 876 | M12: 854 | N12: 1731 | O12: 78 | P12: 427 | Q12: 221 | R12: 128 | S12: 83 | T12: 433 | U12: 238 | V12: 122 | AC12: 82
A13: Jaggampeta | B13: Gandepalle | C13: P.Surampalem | D13: K.Surampalem | E13: Battleground | F13: 2 | G13: Marisetti Gangabhavani | H13: YCP | I13: BC(W) | J13: Setti Balija | K13: 8897945154 | L13: 839 | M13: 757 | N13: 1596 | O13: 37 | P13: 324 | Q13: 235 | R13: 161 | S13: 54 | T13: 360 | U13: 272 | V13: 153 | AC13: 82
... A23: Jaggampeta | B23: Gokavaram | C23: Gadelapalem | D23: Gadelapalem | E23: Battleground | F23: 2 | G23: Atchibabu Kammila | H23: YCP | I23: UR(G) | J23: Kapu | K23: 9443586869 | L23: 748 | M23: 762 | N23: 1510 | O23: 64 | P23: 358 | Q23: 212 | R23: 128 | S23: 61 | T23: 353 | U23: 210 | V23: 124 | AC23: 87
A24: Jaggampeta | B24: Gokavaram | C24: Gangam Palem | D24: Gangam Palem | E24: Battleground | F24: 1 | G24: Doddi Venkata Lakshmi | H24: YCP | I24: UR(W) | J24: Gavara | K24: 9010545620 | L24: 589 | M24: 590 | N24: 1179 | O24: 42 | P24: 266 | Q24: 216 | R24: 66 | S24: 64 | T24: 285 | U24: 164 | V24: 76
A25: Jaggampeta | B25: Gokavaram | C25: Gangam Palem | D25: Takurupalem | E25: Battleground | F25: 1 | G25: Doddi Venkata Lakshmi | H25: YCP | I25: UR(W) | J25: Gavara | K25: 9010545620 | L25: 234 | M25: 263 | N25: 497 | O25: 24 | P25: 114 | Q25: 74 | R25: 50 | S25: 24 | T25: 116 | U25: 53 | V25: 41
A26: Jaggampeta | B26: Gokavaram | C26: Gokavaram | D26: Gokavaram | E26: Battleground | F26: 13 | G26: Sravani Komaram | H26: TDP | I26: ST(W) | J26: Reddika | K26: 9866737300 | L26: 5198 | M26: 5750 | N26: 12062 | O26: 331 | P26: 2678 | Q26: 1727 | R26: 1012 | S26: 345 | T26: 2466 | U26: 1534 | V26: 853 | AC26: 76
A27: Jaggampeta | B27: Gokavaram | C27: Gummalladuddi | D27: Gummalladuddi | E27: Favourable | F27: 2 | G27: Sarakanam Ramalakshmi | H27: YCP | I27: BC(W) | J27: Gavara | K27: 7702072955 | L27: 980 | M27: 998 | N27: 1978 | O27: 35 | P27: 468 | Q27: 318 | R27: 177 | S27: 64 | T27: 465 | U27: 283 | V27: 168 | AC27: 76
A28: Jaggampeta | B28: Gokavaram | C28: Itikayala Palle | D28: Itikayala Palle | E28: Favourable | F28: 1 | G28: Dara Ramakrishna | H28: TDP | I28: UR(G) | J28: Setti Balija | K28: 9849668073 | L28: 515 | M28: 564 | N28: 1079 | O28: 26 | P28: 246 | Q28: 194 | R28: 98 | S28: 30 | T28: 246 | U28: 155 | V28: 84
A29: Jaggampeta | B29: Gokavaram | C29: Kamaraju Peta | D29: Kamaraju Peta | E29: Favourable | F29: 5 | G29: Venkatarao Adapa | H29: TDP | I29: BC(G) | J29: Yadava | K29: 9640604838 | L29: 0 | M29: 0 | N29: 4938 | O29: 0 | P29: 0 | Q29: 0 | R29: 0 | S29: 0 | T29: 0 | U29: 0 | V29: 0
A30: Jaggampeta | B30: Gokavaram | C30: Kothapalle | D30: Kothapalle | E30: Battleground | F30: 7 | G30: Kanchumarthi Katama Swamy | H30: YCP | I30: SC(G) | J30: Mala | K30: 9652219718 | L30: 2868 | M30: 3032 | N30: 5917 | O30: 52 | P30: 531 | Q30: 405 | R30: 343 | S30: 55 | T30: 546 | U30: 431 | V30: 255 | AC30: 78
A31: Jaggampeta | B31: Gokavaram | C31: Krishnuni Palem | D31: Krishnuni Palem | E31: Battleground | F31: 5 | G31: Adilakshmi Rowthu | H31: YCP | I31: UR(W) | J31: Velama | K31: 9359889999 | L31: 1621 | M31: 2071 | N31: 4953 | O31: 129 | P31: 933 | Q31: 644 | R31: 364 | S31: 124 | T31: 811 | U31: 437 | V31: 249 | AC31: 84
A32: Jaggampeta | B32: Gokavaram | C32: Mallavaram | D32: Mallavaram | E32: Battleground | F32: 6 | G32: Idudala Lakshmi | H32: TDP | I32: BC(W) | J32: T.Kapu | K32: 8099534455 | L32: 0 | M32: 0 | N32: 4652 | O32: 0 | P32: 0 | Q32: 0 | R32: 0 | S32: 0 | T32: 0 | U32: 0 | V32: 0 | AC32: 67
A33: Jaggampeta | B33: Gokavaram | C33: Mallavaram | D33: Sivaramapatnam | E33: Favourable | F33: 1 | G33: Idudala Lakshmi | H33: TDP | I33: BC(W) | J33: T.Kapu | K33: 8099534455 | L33: 0 | M33: 0 | N33: 1004 | O33: 0 | P33: 0 | Q33: 0 | R33: 0 | S33: 0 | T33: 0 | U33: 0 | V33: 0 | AC33: 67
A34: Jaggampeta | B34: Gokavaram | C34: Rampa Yerrampalem | D34: Rampa Yerrampalem | E34: Favourable | F34: 7 | G34: Badampudi Harshita | H34: TDP | I34: SC(W) | J34: Mala | K34: 9441596400 | L34: 2589 | M34: 2711 | N34: 5301 | O34: 116 | P34: 1225 | Q34: 826 | R34: 543 | S34: 164 | T34: 1231 | U34: 784 | V34: 409 | AC34: 79
A35: Jaggampeta | B35: Gokavaram | C35: Thanti Konda | D35: Thanti Konda | E35: Battleground | F35: 4 | G35: Satyanarayanamma Baddireddy | H35: YCP | I35: UR(W) | J35: Kapu | K35: 9848106951 | L35: 1660 | M35: 1716 | N35: 3377 | O35: 102 | P35: 785 | Q35: 465 | R35: 364 | S35: 126 | T35: 793 | U35: 433 | V35: 308 | AC35: 78
A36: Jaggampeta | B36: Gokavaram | C36: Tirumalayapalem | D36: Tirumalayapalem | E36: Battleground | F36: 4 | G36: Puramsetti Chandra Sekhar | H36: TDP | I36: UR(G) | J36: Kapu | K36: 9573277999 | L36: 912 | M36: 940 | N36: 2608 | O36: 36 | P36: 407 | Q36: 297 | R36: 200 | S36: 73 | T36: 399 | U36: 285 | V36: 154 | AC36: 87
A37: Jaggampeta | B37: Gokavaram | C37: Vedurupaka | D37: Vedurupaka | E37: Favourable | F37: 2 | G37: Dasari Singaramma | H37: YCP | I37: BC(G) | J37: T.Kapu | K37: 9618328505 | L37: 672 | M37: 700 | N37: 1372 | O37: 44 | P37: 315 | Q37: 213 | R37: 128 | S37: 35 | T37: 351 | U37: 170 | V37: 115
A38: Jaggampeta | B38: Gokavaram | C38: Vedurupaka | D38: Bavojipeta | E38: Safe | F38: 1 | G38: Dasari Singaramma | H38: YCP | I38: BC(G) | J38: T.Kapu | K38: 9618328505 | L38: 370 | M38: 351 | N38: 721 | O38: 19 | P38: 184 | Q38: 89 | R38: 59 | S38: 24 | T38: 203 | U38: 96 | V38: 47
A39: Jaggampeta | B39: Jaggampeta | C39: Gollalagunta | D39: Gollalagunta | E39: Battleground | F39: 2 | G39: Tirumalaraju Kumari | H39: YCP | I39: UR(W) | J39: Kapu | K39: 9505415559 | L39: 680 | M39: 648 | N39: 1328 | O39: 46 | P39: 312 | Q39: 184 | R39: 106 | S39: 77 | T39: 331 | U39: 164 | V39: 108 | AC39: 78
A40: Jaggampeta | B40: Jaggampeta | C40: Govindapuram | D40: Govindapuram | E40: Battleground | F40: 2 | G40: Kammila Venkateswara Rao | H40: TDP | I40: UR(G) | J40: Kamma | K40: 9959432912 | L40: 752 | M40: 795 | N40: 1547 | O40: 65 | P40: 407 | Q40: 189 | R40: 134 | S40: 76 | T40: 395 | U40: 169 | V40: 112 | AC40: 85
A41: Jaggampeta | B41: Jaggampeta | C41: Gurra Palem | D41: Balabhadrapuram | E41: Battleground | F41: 1 | G41: Cheepurupalli Lakshmi | H41: YCP | I41: BC(G) | J41: Velama | K41: 9010126289 | L41: 190 | M41: 176 | N41: 366 | O41: 6 | P41: 95 | Q41: 45 | R41: 30 | S41: 14 | T41: 99 | U41: 45 | V41: 32 | AC41: 80
A42: Jaggampeta | B42: Jaggampeta | C42: Gurra Palem | D42: Gurra Palem | E42: Battleground | F42: 2 | G42: Cheepurupalli Lakshmi | H42: YCP | I42: BC(G) | J42: Velama | K42: 9010126289 | L42: 1039 | M42: 1013 | N42: 2052 | O42: 76 | P42: 506 | Q42: 271 | R42: 160 | S42: 155 | T42: 503 | U42: 262 | V42: 118 | AC42: 80
A43: Jaggampeta | B43: Jaggampeta | C43: Irripaka | D43: Irripaka | E43: Battleground | F43: 4 | G43: Thirri Devi | H43: YCP | I43: BC(W) | J43: T.Kapu | K43: 9885898499 | L43: 1354 | M43: 1436 | N43: 2790 | O43: 57 | P43: 683 | Q43: 413 | R43: 283 | S43: 91 | T43: 675 | U43: 379 | V43: 209 | AC43: 71
A44: Jaggampeta | B44: Jaggampeta | C44: J.Kothuru | D44: J.Kothuru | E44: Battleground | F44: 3 | G44: Nakireddy Nageswara Rao | H44: YCP | I44: UR(G) | J44: Kapu | K44: 9959581167 | L44: 1386 | M44: 1393 | N44: 2779 | O44: 92 | P44: 703 | Q44: 356 | R44: 242 | S44: 120 | T44: 745 | U44: 337 | V44: 182 | AC44: 72
A45: Jaggampeta | B45: Jaggampeta | C45: Jaggampeta | D45: Jaggampeta | E45: Battleground | F45: 18 | G45: Nagaratnam Batchala | H45: YCP | I45: SC(W) | J45: Mala | K45: 9666892228 | L45: 7495 | M45: 8184 | N45: 15688 | O45: 540 | P45: 4108 | Q45: 2248 | R45: 1286 | S45: 566 | T45: 3847 | U45: 1948 | V45: 1134 | AC45: 82
A46: Jaggampeta | B46: Jaggampeta | C46: Jaggampeta | D46: Seethanagaram | E46: Safe | F46: 1 | G46: Nagaratnam Batchala | H46: YCP | I46: SC(W) | J46: Mala | K46: 9666892228 | L46: 466 | M46: 469 | N46: 935 | O46: 39 | P46: 196 | Q46: 137 | R46: 96 | S46: 36 | T46: 191 | U46: 146 | V46: 93 | AC46: 82
A47: Jaggampeta | B47: Jaggampeta | C47: Kandregula | D47: Kandregula | E47: Battleground | F47: 2 | G47: Bodireddy Chakra Rao | H47: YCP | I47: UR(G) | J47: Kapu | K47: 9573060895 | L47: 994 | M47: 936 | N47: 1930 | O47: 64 | P47: 466 | Q47: 256 | R47: 150 | S47: 67 | T47: 541 | U47: 237 | V47: 149 | AC47: 50
A48: Jaggampeta | B48: Jaggampeta | C48: Katravulapalle | D48: Katravulapalle | E48: Battleground | F48: 9 | G48: Pitta Sugunarao | H48: YCP | I48: SC(G) | J48: Mala | K48: 9885244148 | L48: 4324 | M48: 4310 | N48: 8634 | O48: 160 | P48: 2232 | Q48: 1166 | R48: 751 | S48: 301 | T48: 2270 | U48: 1101 | V48: 651 | AC48: 82
A49: Jaggampeta | B49: Jaggampeta | C49: Mallisala | D49: Mallisala | E49: Battleground | F49: 4 | G49: Sarvasiddi Nukaratnam | H49: YCP | I49: BC(W) | J49: Yadava | K49: 9951526664 | L49: 1754 | M49: 1766 | N49: 3520 | O49: 101 | P49: 842 | Q49: 479 | R49: 344 | S49: 126 | T49: 935 | U49: 434 | V49: 257 | AC49: 87
...

Sheet Data
A1: S No | B1: Assembly | C1: Mandal | D1: Panchayat | E1: Village | F1: Current Sarpanch | G1: Sarpanch Current Party | H1: TDP Current Position | I1: 2024 GE Scenario | J1: 2020 Sarpanch Election Scenario | K1: Possible Reservation for Upcoming Panchayat Elections | L1: 2026 Sarpanch Aspirants - Aspirant Number - Aspirant Party - Aspirant Faction | M1: Key Leaders - Leader Mobile - Party - Faction | N1: Internal Factions | O1: Development Activities (2024-2026) | P1: Key Issues in Panchayat | Q1: Illegal Activities | R1: Any Aditional Information
A2: =ROW(A1) -> 1 | C2: Gollaprolu | D2: A.K.MALLAVARAM | F2: Satyanarayanamma Arigela - 9705934446
A3: =ROW(A2) -> 2 | C3: Gollaprolu | D3: A.P.Mallavaram | F3: Kadimasetti Suseela - 9666243208
A4: =ROW(A3) -> 3 | C4: Gollaprolu | D4: A.VIJAYANAGARAM | F4: M Satya Venkata Sita Ramakrishna Raju - 9618222288
A5: =ROW(A4) -> 4 | C5: Gollaprolu | D5: CHEBROLU | F5: Dondapati Lovathalli - 7386093635
A6: =ROW(A5) -> 5 | C6: Gollaprolu | D6: CHENDURTHI | F6: Alli Papa - 6281745507
A7: =ROW(A6) -> 6 | C7: Gollaprolu | D7: CHINA JAGGAMPETA | F7: Vammi Veeralakshmi - 9959354489
A8: =ROW(A7) -> 7 | C8: Gollaprolu | D8: Durgada | F8: Pampana Subbalakshmi - 9290933688
A9: =ROW(A8) -> 8 | C9: Gollaprolu | D9: KODAVALI | F9: Burra Naga Ramachandra - 9866027338
A10: =ROW(A9) -> 9 | C10: Gollaprolu | D10: TATIPARTHI | F10: Katta Bulleswararao - 9848074541
A11: =ROW(A10) -> 10 | C11: Gollaprolu | D11: VANNEPUDI | F11: Kanda Subrahmanyam - 9848657992
A12: =ROW(A11) -> 11 | C12: Kakinada Rural | D12: GANGANAPALLI | F12: Geesala Mahalakshmi - 9160699909
A13: =ROW(A12) -> 12 | C13: Kakinada Rural | D13: KOVVADA | F13: Kotipalli Uma - 9966097546
... A106: =ROW(A105) -> 105 | C106: U.Kothapalli | D106: YENDAPALLI | F106: Pedda Apparao Seelam - 7013609519
A107: =ROW(A106) -> 106 | B107: Jaggampeta | C107: Gandepalli | D107: Borrampalem | F107: Pokala Subbarao - 9705171931 | G107: YSRCP | H107: Battleground | I107: In General election TDP got good majority ove YCP, Sarpanch is extremely disgruntled with how YCP handled local leaders taking away sarpanch powers funds, the money distribution during the elections were also not in control of the Sarpanch. The village is domianted by BC comminity especially Pereka. | J107: This is predominantly a INC and YCP supported village, this foundationala support along with YSRCP being in power led to a decent win for YCP contestant. | K107: BC (Gen) | L107: Pokala Subbarao (Perika) will contest if the reservation is BC or general. | M107: Pokala Subbarao YCP and his close family member Pallapu Vishnu Chakram (Ex-Sarpanch) are key leaders in YCP, Kalapu Subbarao and his relative Yerramsetti Chandra Rao (Babji) his wife Venkatalaxmi (Ex-ZPTC) are key leaders in TDP.
A108: =ROW(A107) -> 107 | B108: Jaggampeta | C108: Gandepalli | D108: Gandepalli | E108: Gandepalli | F108: Rutthala Lalitha Devi - 6300566579 | G108: YSRCP | H108: Favourable | I108: This village is dominated by Kamma community where TDP secured majority in 2014 and 2019 AEs despite losing the elections due to Kamma's influence on Koppula Velama community. Palakurthi Aadi Narayana (Cluster Incharge) and Pyla Venkanna (Sarpanch Contestant) are very active in TDP. Bodha Rami Reddy (YSRCP- Village President) is leading the YSRCP along with Maddipatla Rama Krishna (MPTC- Kamma). Bodha Rami Reddy is close to Muthyala Srinivas (Ex AC Incharge of YSRCP -2016) and proposing hsi name for YSRCP Incharge. | K108: General | L108: Maddipatla Rama Krishna (Kamma- YSRCP - Ex -MPTC) | P108: 1. Draniage is key issue in Gandepalli Village 2. 250 Housing Sites were allotted near Polavaram Canal where houses construction not materialised
A109: =ROW(A108) -> 108 | B109: Jaggampeta | C109: Gandepalli | D109: K.Gopalapuram | E109: K.Gopalapuram | F109: Karri Suryakantham - 9502562392 | G109: YSRCP | H109: Favourable | I109: TDP was able to secure the majority of 280 votes in the village as Village YSRCP is divided into 2 Groups, Karri Ramanjaneyulu (Thota Narsimham's group) and Parthasarthi (Jyothula Chanti Babu Group) which helped TDP MLA Nehru in elections. Parthasarathi owns around 100 acres in village belongs to Karnam community stayed neutral in elections. On the other hand TDP is led by Bala Subramanyam (Karnalu - Babai of Parthasarathi) who is a 3 times Sarpanch and holds good support in village. Bala Subramanyam stays in Rajahmundry and owns house in the village | J109: Karri Suryakantham was unanimously elected as Sarpanch with YSRCP support | K109: General | L109: 1.Parthasarathi (YSRCP- Karnalu - Financially Strong 2. Bala Subramanyam (TDP -Karnalu -3 times Sarpanch) | M109: 1. Karri Krishna (YSRCP -Turpu Kapu - Active Member of Party) 2. Karri Ramanjaneyulu (YSRCP - Turpu Kapu - Sarpanch Husband) | O109: 1. Road connecvity from K. Gopalapuram to Gandepalli Via NT Rajapuram is completely damaged
A110: =ROW(A109) -> 109 | B110: Jaggampeta | C110: Gandepalli | D110: K.Nayakampalli | F110: Mallireddy Mahalakshmi Varahalu - 9441246682
A111: =ROW(A110) -> 110 | B111: Jaggampeta | C111: Gandepalli | D111: Mallepalli | F111: Ballireddy Varalakshmi - 9493839571 | G111: YSRCP | H111: Battleground | I111: TDP got majority in the village, Domma Srinu (Kapu) joined TDP from YCP before elections. | J111: YCP sarpanch Balireddy Varalaxmi wife of Gangaraju won with 1300 votes majority, with 2 MPTC and 10 wards while TDP got 4 wards, Gangaraju does politics without parties and have good relations with everyone, he is a pastor and the village have more than 400 Christians. | K111: General | L111: Ramkurthi Narasimha-JSP-Kapu Balireddy Gangaraju-Turpu Kapu-YCP-Pastor Domma Srinu-Kapu-TDP | M111: Ramkurthi Narasimha-JSP-Kapu Balireddy Gangaraju-Turpu Kapu-YCP-Pastor Domma Srinu-Kapu-TDP | P111: The village only has dirt roads and gravel roads, the village is in need of CC roads.
A112: =ROW(A111) -> 111 | B112: Jaggampeta | C112: Gandepalli | D112: Murari | F112: Kukkala Ananda Babu - 9949147450 | G112: TDP | H112: Favourable | I112: TDP got 500 votes majority in this village in the elections. | J112: There was no election, the decision was unanimous, Chinnam Matha mother of Chinnam Duragao rao tried to contest but the village farmers decided for unanimous decision, TDP was not eager in participating in the elections. | K112: General | L112: The village might got for unanimous this time as well, late Kondaiah Dora's brother Chittibabu who is from Z Ragampeta used to involve alot in the village politics but not involved now. OC General reservation in the village might stimualte a strong rivalry in the village if Chengala Dorababu (Kamma) YCP decide to contest, against any candidate fielded by Jasthi Vasanth son of Kondaiah Dora | O112: CC roads are needed Community hall is expected by the village
A113: =ROW(A112) -> 112 | B113: Jaggampeta | C113: Gandepalli | D113: N.T.Rajapuram | F113: Bikkina Devi Durga - 8309596673 | G113: TDP | H113: Favourable | I113: TDP got 330 votes majority major YCP leaders like Parimi Veera Venkata Sathyanarayana (Parimibabu) ZPTC and sarpanch Bikkina Devi wife of Bikkina gangadher joined TDP right before elections. | J113: Kathina Santhosh Kumar wife of Kathina Venkanna Chowdhary was the original YCP candidate and Bikkina Devi is the rebel candidate from YCP there was no canddiate from TDP, rebel candidate won with the support of Parimbabu in the elections. Kathina Venkanna Chowdhary also came to TDP before elections he is a follower of Chantibabu and went to YCP with Chantibabu from TDP before. He is with the Kantipudi Sathyanarayana group in TDP now. | K113: SC (Gen) | L113: Kantipudi Sathayanarayana TDP, and parimbabu TDP are two groups in the village now, Parimbabu is ZPTC and Bikkina Devi Durga are one group now after joining TDP, he is accused of 23 crores of fraud in DCCB with ED and money laundering cases. Kantipudi Sathyanarayana was Agriculturte society president and PAC chairman before. Parimi Venkateshwar Rao (YCP) (ex sarpanch) but might not contest as TDP might be in two factions but he might get support from Parimbabu if party orders prevent Parimbabu to contest a candidate. Parimbabu have Bikkina Ramana, Bikkina Vamshi, Bikkina Venkat rao and Palacharla Sathyanarayna in line to contest as sarpanch candidates they are all his relatives. Parimbabu was society chairman from TDP in 2004 and went to YCP around 2011 with Nehru, he came back with Nehru 2017, he went to YCP in 2019, he is having CB CID enquiry. people are angry with them as his scams made the banks hike the interest rates. | P113: The village have alot of oil palms and Thalluri lift irrigation is important to this village as the village ground water is depleteed now and need this water to even feed their cattle, the bill is granted but the contract is not started yet, House spaces promised by TDP are also a point of contention from people now. village needs drainages and cemetary, Naveen has negative view because he is encouraging Parimbabu, and there is alot of gravel mining in this village and neighbouring village Gopalpuram, the road contract from Yellamilli to Gopalpuram is only completed 50% becasue the gravel lorries will destroy the road and the contractor wont get the bill, mining lorries were issue for people and MLA asked them to do it only at night now and not allowing in day time, people believe MLA has percentage in this.
A114: =ROW(A113) -> 113 | B114: Jaggampeta | C114: Gandepalli | D114: NEELADRIRAOPETA | F114: Mulampaka Suresh Babu - 9059315666 | G114: YSRCP | H114: Battleground | I114: TDP got a comfortable 1500 over YCP | J114: There were strong contestants from TDP, YCP and JSP as well here but YCP got 830 votes majoriy, Nakka Manish (Sagara) from TDP and Darballa Sadguru Murthy from (JSP) contested, from TDP Gajji Laxmi (Yadava) also contested in the elections. | K114: General | L114: There is a chance for rebel nominations in TDP, Chityala Babji (Kapu) Kurukuri Venkatesh Chowdhary (Kamma), Palla Prasad (Kapu) TDP, Suresh Babu (Sagara) YCP, Nakka Venkateshwar Rao (Sagara) and Nakka Annavaram Sathyanarayana Murthy might contest with the support of Suresh Babu | M114: Darballa Rambabu (ex Sarpanch) Nakka Venkateshwar Rao (YCP) Kurukuri Venkatesh Chowdhary Kamma TDP Dareballa Sadhguru (JSP) | N114: Sarpanch is supporter of Narasimha and claims the cadre here is party loyal and not candidate loyal, claimed Narasimha organized weekly meetings with cadre every week and visits some one every week. | O114: Pushkar canal bridge, water tanks facility in the village
A115: =ROW(A114) -> 114 | B115: Jaggampeta | C115: Gandepalli | D115: P.Nayakampalli | F115: Mallireddy Annapurna - 9692879999 | G115: YSRCP | H115: Battleground | I115: TDP got 280 majority in this village over YCP, YCP Sarpanch Annapurna's Husband Mallireddy Venkataramana passed away his brother Mallireddy Suresh takes care of things now. | J115: There was no election, it was unanimous, TDP cadre was not willing to participate and TDP Ex-sarpanch from previous term moved to YCP before 2019 elections. | K115: BC (Woman) | L115: Dammu Apparao (Settibalija) YCP Chemmangi Srinu (Settibalija) TDP school committee chairman Medisetti Subbarai (Settibalija) TDP | M115: Malireddy Suresh (Kamma) YCP Vundavalli Narayana Murthy (Kamma) YCP Ex-sarpanch Vundavalli Chandra Rao (TDP) Ex MPTC Kamma
A116: =ROW(A115) -> 115 | B116: Jaggampeta | C116: Gandepalli | D116: Ramayyapalem | F116: Mylavarapu Venkatalakshmi - 9618098937 | G116: YSRCP | H116: Battleground | I116: - Jyothula Nehru has got a majority of 260 votes (543 for TDP and 283 for YSRCP) - Village is fully dominated by Turpu Kapu | J116: - Contestants include Mylavarapu Srinivas (Defacto Sarpanch for his Wife | YSRCP) and Golavilli Babu Rao (TDP | Ex-Sarpanch 2014) - Mylavarapu Srinivas has won with a majority of 220 votes (Got around 500) over Baburao (got around 280 votes) - Mylavarapu Srinivas was backed by Chantibabu during the Sarpanch elections but he is currently with Thota Narasimham - Kona Peddhayya(Currently TDP - Nehru), a 3 term sarpanch before 2014 still has his candidates stood up in sarpanch elections | K116: BC (Gen) | L116: - Rowthu Sathibabu, relatively a cousin to current Sarpanch Srinivas, and belongs to Thota Narasimham's faction is the major aspirant from YSRCP - Kona Peddhayya will have one of his candidates in the race from TDP - Babu Rao, Ex- Sarpanch-2014; Contestant 2020, is also in the race from TDP - But both Babu Rao and Kona Peddhayya are in Jyothula Nehru's faction - Golavilli Annavaram, elder brother of Golavilli Baburao also has differences | N116: - TDP has two major factions: 1 - Kona Peddhayya; and 2 - Golavilli Babu Rao - YSRCP has Rowthu Sathibabu (2026 aspirant) and Mylavarapu Srinivas (Defacto Sarpanch-2020) factions but as Srinivas is not expecting ticket for YSRCP is likely to support Sathibabu during the elections | O116: - No development activities in the new tenure | P116: - Severe drinking water scarcity - Irrigation water scarcity
A117: =ROW(A116) -> 116 | B117: Jaggampeta | C117: Gandepalli | D117: Singarampalem | F117: Buddaraju Ganapathiraju - 9882298866
A118: =ROW(A117) -> 117 | B118: Jaggampeta | C118: Gandepalli | D118: SUBBAYAMMA PETA | F118: Bobbara Sivakumar - 9492885777
A119: =ROW(A118) -> 118 | B119: Jaggampeta | C119: Gandepalli | D119: Surampalem | F119: Marisetti Gangabhavani - 8897945154
A120: =ROW(A119) -> 119 | B120: Jaggampeta | C120: Gandepalli | D120: Talluru | F120: Seelamanthula Veerababu - 8309719191 | G120: TDP | H120: Favourable | I120: - Jyothula Nehru has got a majority of around 670 votes - Param Cherla Sathyanarayana (Ex Sarpanch | Kamma), Paindi Venkateshwarav Rao(Ex Sarpanch | Kamma) and Seelamanthula Veerababu (Sarpanch | Padmashali | Converted Christian) are the major TDP leaders whose support has brought reasonable Kamma, SC and BC (Padmashali and Yadava) | J120: - Seelamanthula Veerababu (Sarpanch | Padmashali | Converted Christian) was in YSRCP during the general elections but came into TDP party on the understanding between him and Param Cherla Sathyanarayana, Paindi Venkateshwarav Rao as the village is dominated by TDP mostly - It was BC(G) reservation for which Seelamanthula Veerababu who is aspiring for political benefits has contested with own resources - Anivelli Rambabu (Dummy candidated from YSRCP), supported by Obinni Veerababu was the contestant against current sarpanch Seelamanthula Veerababu. - Seelamanthula Veerababu has won with a majority of 227 votes | K120: SC (Woman) | L120: - One backed by Obinni Veerababu from YSRCP - One backed by Param Cherla Sathyanarayana and Paindi Venkateshwarav Rao from TDP, if SC or one among these if its General | N120: - YSRCP has no major faction but just one Obinni Veerababu who is with Thota Narasimham - TDP may split to two if Param Cherla Sathyanarayana and Paindi Venkateshwarav Rao does not back current sarpanch Seelamanthula Veerababu | O120: - CC Roads worth 50 Lakhs with a stretch of 1.5 KM - Cemetary for BCs | P120: - Cemetary for SCs - 2-3 internal roads
A121: =ROW(A120) -> 120 | B121: Jaggampeta | C121: Gandepalli | D121: Uppalapadu | F121: Adabala Ramanjaneyulu - 9951557676 | G121: TDP | H121: Favourable | I121: - Jyothula Nehru has got a majority of around 650 votes against Thota Narasimham - Adabala family who are in TDP and village being dominated by Kapu community has helped get the majority | J121: - Adabala Ramanjaneyulu (Sarpanch) has won with a majority of around 200 votes against Ramakurthy Ramakrishna Murthy - Adabala Ramanjaneyulu actually won from YSRCP but later joined TDP - Adabala Ramanjaneyulu's brother Adabala Bhasker had differences but they both are currently in TDP - Ramakurthy Ramakrishna Murthy actully contested two times and lost both the times. | K121: SC (Woman) | L121: - Adabala Anjaneyulu is ready to contest the elections if he gets support from the party and Ramakurthy Ramakrishna Murthy will be the other contestant supported by Thota Narasimham | N121: - Currently no major internal factions in both the parties but there is a chance of TDP becoming two getting divided betwen Adabala brothers | O121: - 3KM CC roads were laid and another 6 KM roads are sanctioned | P121: - Drianage system must be improvised
A122: =ROW(A121) -> 121 | B122: Jaggampeta | C122: Gandepalli | D122: Yellamilli | F122: N. Naga Jyothi - 9502850451
A123: =ROW(A122) -> 122 | B123: Jaggampeta | C123: Gandepalli | D123: Yerrampalem | F123: Ijjina Chinnari - 8897265258
A124: =ROW(A123) -> 123 | B124: Jaggampeta | C124: Gandepalli | D124: Z.Ragampeta | F124: Sri Kandula Chittibabu - 9618721999
A125: =ROW(A124) -> 124 | B125: Jaggampeta | C125: Jaggampeta | D125: GOLLALAGUNTA | F125: Tirumalaraju Kumari - 9505415559
A126: =ROW(A125) -> 125 | B126: Jaggampeta | C126: Jaggampeta | D126: GOVINDAPURAM | F126: Kammila Venkateswara Rao - 9959432912
A127: =ROW(A126) -> 126 | B127: Jaggampeta | C127: Jaggampeta | D127: GURRAPPALEM | F127: Cheepurupalli Lakshmi - 9010126289
A128: =ROW(A127) -> 127 | B128: Jaggampeta | C128: Jaggampeta | D128: IRRIPAKA | F128: Thirri Devi - 9885898499 | G128: YSRCP | H128: Favourable | I128: This is the native village of Nehru even Chanti Babu supported fully after he is denied ticket in YSRCP.TDP was able to secure the majority of around 800 votes. Pantham Babu ( - Previously contested against Jyothula Naveen's Wife -Close to Thota Narsimham) shifted to TDP during 2024 elections after he was promised Sarpanch seat in local elections | J128: Tirri Devi (W/o Tirri Venkat Ramana - Previously close to Chanti Babu) secured Sarpanch position with 396 votes majority against Surla Satyavathi (Velama - suppoorted by Nehru), later supported Thota Narsimham in assembly elections. | K128: General | M128: 1. Tirri Venkata Ramana (YSRCP - T.Kapu - Sarpanch Husband) 2. Yalla Ramana (YSRCP - T.Kapu - Active Leader) 2. Pantham Babu (Kapu -TDP - Shifted frpm YSRCP in 2024 - Sarpanch Contestant) 3. Jyothula Naga Babu (TDP -Kapu - Close to Jyothula Naveen) | P128: 1. High school should be upgraded to 10th class, adject villages Mamidada, Somavaram already upgraded to 10th 2. Irrigation water is the major issue, though Yeleru canal passes through village only Nehru and Chanti Babu and few others pump throgh motors and charges 6,000 per farmer to supply the water to them 3. 220 Housing pattas sanctioned even 2 acres of land bought during YSRCP government but not materialised
A129: =ROW(A128) -> 128 | B129: Jaggampeta | C129: Jaggampeta | D129: J.KOTHURU | F129: Nakireddy Nageswara Rao - 9959581167
A130: =ROW(A129) -> 129 | B130: Jaggampeta | C130: Jaggampeta | D130: JAGGAMPETA | F130: Nagaratnam Batchala - 9666892228 | G130: YSRCP | H130: Battleground | I130: TDP MLA candidate Jyothula Nehru was able to secure 4042 votes due to | J130: Jaggampeta Village is reserved for SC (W) where Bandaru Raja (Vice Sarpanch) handled all the elections and played second fidel to MLA Chanti Babu. The margin for Sarpanch election is around 800 votes against TDP candidate Sambatula Susheela. | K130: BC (Gen) | L130: Pandrangi Ram Babu (TDP - Turpu Kapu - Senior Leader - ZPTC Contestant) Rayi Sai (Kapu - Close to Chanti Babu - later joined TDP) | M130: Bandaru Raja (YSRCP - Kapu - Vice Sarpanch) Chittamani Satya Narayana (MPTC - Setti Balija - YCP) Jeeni Mani Babu (Kapu - YSRCP) Rayi Sai (Youth Leader - Kapu) Vommi Raghu Ram (ZPTC - Yadava - YSRCP) | N130: YSRCP divided into 2 Groups Bandaru Raja (Kapu - Vice Sarpanch - YSRCP) Ghafoor (Senior leader) TDP divided into 2 Groups Marisetty Badram (Kapu - TDP - Senior leader) Jeeni Manikyala Rao (JVR - Kapu - Mandal President) | P130: 1. Drainage is the major issue in Jaggampeta 2. Internal Roads in Jaggampeta Village
A131: =ROW(A130) -> 130 | B131: Jaggampeta | C131: Jaggampeta | D131: KANDREGULA | F131: Bodireddy Chakra Rao - 9573060895
A132: =ROW(A131) -> 131 | B132: Jaggampeta | C132: Jaggampeta | D132: KATRAVULAPALLE | F132: Pitta Sugunarao - 9885244148 | G132: YSRCP | H132: Favourable | I132: TDP got more than 3000 majority in this region, the Kapu voter base of YSRCP moved towards the TDP JSP alliance, TDP also had strong leaders in the village who are financially able to manage the party. | J132: The SC reservation seat went to YSRCP where the MLA intentionally changed the reservation to SC to favour the party. As the government was also in power YSRCP was able to win easily as TDP did not work hard to win. | K132: General | L132: Yeleti Bobby (Kamma)-TDP (strong leader in village) Yeleti Dhanukonda (Kamma)-YCP (Grand father was Sarpanch) | M132: Yeleti Bobby (Kamma) TDP Bindani brothers Bindali Perraju and Arjun Rao Perraju is YCP committee president.
...

Sheet Key Leaders
A1: Assembly | B1: Mandal | C1: Panchayat | D1: Rank | E1: Full Name | F1: Caste | G1: Category | H1: Party | I1: Political Designations | J1: Mobile | K1: Influence | L1: Description

Sheet Back End
A1: Assembly | B1: Mandal | C1: Panchayat | D1: Panchayat / Village / Hamlet | E1: {=A:A&"-"&B:B&"-"&C:C&"-"&D:D} -> Assembly-Mandal-Panchayat-Panchayat / Village / Hamlet | F1: Filtered Mandal | G1: Filtered Village | H1: TDP | I1: TDP Ahead | J1: Strong | K1: Infrastructure | L1: UPTO 50 Votes | M1: Acharyulu | N1: OC
A2: Jaggampeta | B2: Gandepalle | C2: Borrampalem | D2: Borrampalem | E2: Jaggampeta-Gandepalle-Borrampalem-Borrampalem | F2: =IFERROR(__xludf.DUMMYFUNCTION("unique(filter(B:B,A:A=Dashboard!A2))"),"#N/A") -> #N/A | G2: =IFERROR(__xludf.DUMMYFUNCTION("arrayformula(sort(proper(filter(D:D,A:A=Dashboard!A2,B:B=Dashboard!D2)),1,true))"),"#N/A") -> #N/A | H2: YSRCP | I2: TDP Closely Ahead | J2: Medium | K2: Drinking Water | L2: UPTO 100 Votes | M2: Adhivelama | N2: BC
A3: Jaggampeta | B3: Gandepalle | C3: Gandepalle | D3: Gandepalle | E3: Jaggampeta-Gandepalle-Gandepalle-Gandepalle | H3: JSP | I3: Split between YSRCP & TDP | J3: Weak | K3: Government Schemess | L3: UPTO 200 Votes | M3: Agnikula Kshatriya | N3: SC
A4: Jaggampeta | B4: Gandepalle | C4: K. Nayakampalle | D4: K. Nayakampalle | E4: Jaggampeta-Gandepalle-K. Nayakampalle-K. Nayakampalle | H4: BSP | I4: JSP Ahead | K4: Irrigation Facilities | L4: Above 200 Votes | M4: Ayyerula | N4: ST
A5: Jaggampeta | B5: Gandepalle | C5: K.Gopalapuram | D5: K.Gopalapuram | E5: Jaggampeta-Gandepalle-K.Gopalapuram-K.Gopalapuram | H5: CPI / CPM | I5: Split between YSRCP & JSP | K5: Lack of Funds to GPs | L5: Above 600 Votes | M5: Balija | N5: Others BC
A6: Jaggampeta | B6: Gandepalle | C6: Mallepalli | D6: Mallepalli | E6: Jaggampeta-Gandepalle-Mallepalli-Mallepalli | I6: YSRCP Ahead | K6: Prevalent Liquor | M6: Battarajulu | N6: Others SC
A7: Jaggampeta | B7: Gandepalle | C7: Mallepalli | D7: Pathuru | E7: Jaggampeta-Gandepalle-Mallepalli-Pathuru | I7: YSRCP Closely Ahead | K7: Illegal Sand Mining | M7: Bondeelu | N7: Others ST
A8: Jaggampeta | B8: Gandepalle | C8: Murari | D8: Murari | E8: Jaggampeta-Gandepalle-Murari-Murari | I8: JSP Closely Ahead | K8: Sanitization | M8: Brahmin
A9: Jaggampeta | B9: Gandepalle | C9: N.T.Rajapuram | D9: N.T.Rajapuram | E9: Jaggampeta-Gandepalle-N.T.Rajapuram-N.T.Rajapuram | I9: Split between JSP & TDP | K9: Other Issues | M9: Budaga Gangali
A10: Jaggampeta | B10: Gandepalle | C10: Neeladriraopeta | D10: Neeladriraopeta | E10: Jaggampeta-Gandepalle-Neeladriraopeta-Neeladriraopeta | I10: Split between YSRCP, TDP & JSP | M10: Budaga Jungaalu
A11: Jaggampeta | B11: Gandepalle | C11: P. Nayakampalle | D11: P. Nayakampalle | E11: Jaggampeta-Gandepalle-P. Nayakampalle-P. Nayakampalle | I11: NA | M11: Chittikarnalu
A12: Jaggampeta | B12: Gandepalle | C12: P.Surampalem | D12: P.Surampalem | E12: Jaggampeta-Gandepalle-P.Surampalem-P.Surampalem | M12: Mani Dora
A13: Jaggampeta | B13: Gandepalle | C13: P.Surampalem | D13: K.Surampalem | E13: Jaggampeta-Gandepalle-P.Surampalem-K.Surampalem | M13: Christian
A14: Jaggampeta | B14: Gandepalle | C14: Ramayyapalem | D14: Ramayyapalem | E14: Jaggampeta-Gandepalle-Ramayyapalem-Ramayyapalem | M14: Dasari
A15: Jaggampeta | B15: Gandepalle | C15: Singarampalem | D15: Singarampalem | E15: Jaggampeta-Gandepalle-Singarampalem-Singarampalem | M15: Devanga
A16: Jaggampeta | B16: Gandepalle | C16: Subbayamma Peta | D16: Subbayamma Peta | E16: Jaggampeta-Gandepalle-Subbayamma Peta-Subbayamma Peta | M16: Dommarlu
A17: Jaggampeta | B17: Gandepalle | C17: Talluru | D17: Talluru | E17: Jaggampeta-Gandepalle-Talluru-Talluru | M17: Dora
A18: Jaggampeta | B18: Gandepalle | C18: Uppalapadu | D18: Uppalapadu | E18: Jaggampeta-Gandepalle-Uppalapadu-Uppalapadu | M18: Dudekula
A19: Jaggampeta | B19: Gandepalle | C19: Yellamilli | D19: Yellamilli | E19: Jaggampeta-Gandepalle-Yellamilli-Yellamilli | M19: Gangireddula
A20: Jaggampeta | B20: Gandepalle | C20: Yerrampalem | D20: Yerrampalem | E20: Jaggampeta-Gandepalle-Yerrampalem-Yerrampalem | M20: Ganjam
A21: Jaggampeta | B21: Gandepalle | C21: Z.Ragampeta | D21: Z.Ragampeta | E21: Jaggampeta-Gandepalle-Z.Ragampeta-Z.Ragampeta | M21: Gavara
A22: Jaggampeta | B22: Gokavaram | C22: Atchutapuram | D22: Atchutapuram | E22: Jaggampeta-Gokavaram-Atchutapuram-Atchutapuram | M22: Gowda
A23: Jaggampeta | B23: Gokavaram | C23: Gadelapalem | D23: Gadelapalem | E23: Jaggampeta-Gokavaram-Gadelapalem-Gadelapalem | M23: Iyyarakala
... A92: Kakinada Rural | B92: Kakinada (Rural) | C92: S. Atchuthapuram | D92: S. Atchuthapuram | E92: Kakinada Rural-Kakinada (Rural)-S. Atchuthapuram-S. Atchuthapuram | M92: Pamula
A93: Kakinada Rural | B93: Kakinada (Rural) | C93: Sarpavaram | D93: Sarpavaram | E93: Kakinada Rural-Kakinada (Rural)-Sarpavaram-Sarpavaram
A94: Kakinada Rural | B94: Kakinada (Rural) | C94: Suryarao Peta | D94: Suryarao Peta | E94: Kakinada Rural-Kakinada (Rural)-Suryarao Peta-Suryarao Peta
A95: Kakinada Rural | B95: Kakinada (Rural) | C95: Swamynagar | D95: Swamynagar | E95: Kakinada Rural-Kakinada (Rural)-Swamynagar-Swamynagar
A96: Kakinada Rural | B96: Kakinada (Rural) | C96: Thammavaram | D96: Thammavaram | E96: Kakinada Rural-Kakinada (Rural)-Thammavaram-Thammavaram
A97: Kakinada Rural | B97: Kakinada (Rural) | C97: Thimmapuram | D97: Thimmapuram | E97: Kakinada Rural-Kakinada (Rural)-Thimmapuram-Thimmapuram
A98: Kakinada Rural | B98: Kakinada (Rural) | C98: Toorangi | D98: Toorangi | E98: Kakinada Rural-Kakinada (Rural)-Toorangi-Toorangi
A99: Kakinada Rural | B99: Kakinada (Rural) | C99: Vakalapudi | D99: Vakalapudi | E99: Kakinada Rural-Kakinada (Rural)-Vakalapudi-Vakalapudi
A100: Kakinada Rural | B100: Kakinada (Rural) | C100: Valasapakalu | D100: Valasapakalu | E100: Kakinada Rural-Kakinada (Rural)-Valasapakalu-Valasapakalu
A101: Kakinada Rural | B101: Karapa | C101: Aratlakatta | D101: Aratlakatta | E101: Kakinada Rural-Karapa-Aratlakatta-Aratlakatta
A102: Kakinada Rural | B102: Karapa | C102: G. Bhavaram | D102: G. Bhavaram | E102: Kakinada Rural-Karapa-G. Bhavaram-G. Bhavaram
A103: Kakinada Rural | B103: Karapa | C103: Goddatipalem | D103: Goddatipalem | E103: Kakinada Rural-Karapa-Goddatipalem-Goddatipalem
A104: Kakinada Rural | B104: Karapa | C104: Gorripudi | D104: Gorripudi | E104: Kakinada Rural-Karapa-Gorripudi-Gorripudi
... A378: Pithapuram | B378: Pithapuram Town | C378: Pithapuram Town | D378: Pithapuram Town | E378: Pithapuram-Pithapuram Town-Pithapuram Town-Pithapuram Town
A379: Pithapuram | B379: Gollaprolu Town | C379: Gollaprolu Town | D379: Gollaprolu Town | E379: Pithapuram-Gollaprolu Town-Gollaprolu Town-Gollaprolu Town | K379: Jaggampeta-Jaggampeta-Vengayamma Puram
A380: Prathipadu | B380: Yeleswaram Town | C380: Yeleswaram Town | D380: Yeleswaram Town | E380: Prathipadu-Yeleswaram Town-Yeleswaram Town-Yeleswaram Town | K380: Jaggampeta-Kirlampudi-Bhupalapantam
A381: Peddapuram | B381: Peddapuram Town | C381: Peddapuram Town | D381: Peddapuram Town | E381: Peddapuram-Peddapuram Town-Peddapuram Town-Peddapuram Town | K381: Jaggampeta-Kirlampudi-Burugupudi
...

Sheet Raw Data - Field Input
A1: Assembly | B1: Mandal Name | C1: GP Name | D1: Village Hamlet | E1: Current Categorisation | F1: Field Categorisation | G1: Seat Call | H1: Top Cohorts in the Village | I1: Reasons for Win/ Loss in 2019 Elections | J1: Elaboration of the Reason | K1: Current Party Positioning | L1: Reasoning for Party Positioning | M1: TDP Assesment | N1: Reasoning | O1: YSRCP Assesment | P1: Reasoning | Q1: JSP Assesment | R1: Reasoning | S1: Perception on the Government | T1: Reasoning | U1: Remarks | V1: Field Remarks | W1: Status | Y1: Created by
A2: Pithapuram | B2: Gollaprolu | C2: =IFERROR(__xludf.DUMMYFUNCTION("filter('Back End'!C:C,'Back End'!A:A=A2,'Back End'!B:B=B2,'Back End'!D:D=D2)"),"#REF!") -> #REF! | D2: KODAVALI | E2: Safe | G2: TDP Ahead | H2: 1. Farmers 2. Fisherman | I2: Caste Composition | J2: 1.SVSN Varma has followed a divide and rule policy in two different castes(kapu and mala) which led to a change of decision in the vote bank. | K2: TDP>YCP>JSP | L2: 1. Due to the leader's reputation in the castes of Mala and Settibalija, TDP had a sizable vote base from the beginning. 2. If TDP and JSP are having an alliance then there is a great chance of a huge vote bank. | M2: Strong | N2: Strong Cadre and Strong Leadership | O2: Medium | P2: Strong Cadre and Strong Leadership | Q2: Strong | R2: Strong Cadre and Strong Leadership | S2: Positive | T2: Positive Image Welfare Schemes | W2: Review
A3: Prathipadu | B3: Prathipadu | C3: =IFERROR(__xludf.DUMMYFUNCTION("filter('Back End'!C:C,'Back End'!A:A=A3,'Back End'!B:B=B3,'Back End'!D:D=D3)"),"#REF!") -> #REF! | D3: Uttarakanchi | E3: Safe | G3: TDP Ahead | H3: 1. Farmers | I3: Caste Composition | J3: 1.This is a Kapu-dominated village and JSP was able to secure more of the Kapu vote bank which split the YCP vote Bank. 2.YCP won over JSP with a very small majority of 11 votes. 3.TDP was able to consolidate the vote bank from Maximum BC Communities ( Senapathulu, Settibalija, and Rajaka) | K3: YCP>TDP>JSP | L3: 1. The JSP & TDP alliance will be the crucial factor in securing the Kapu vote bank along with BC communities. 2)TDP has a strong hold in BC Communities (Yadava). 3) YCP has the majority of the vote bank from SC Community Mala | M3: Strong | N3: Strong Cadre and Strong Leadership | O3: Weak | P3: Weak Leadership & Weak Cadre | Q3: Strong | R3: Strong Cadre and Strong Leadership | S3: Negative | T3: No Development | W3: Complete
A4: Prathipadu | B4: Sankhavaram | C4: =IFERROR(__xludf.DUMMYFUNCTION("filter('Back End'!C:C,'Back End'!A:A=A4,'Back End'!B:B=B4,'Back End'!D:D=D4)"),"#REF!") -> #REF! | D4: Mandapam | E4: Battleground | F4: TDP Closely Ahead | G4: TDP Closely Ahead | H4: 1. Paddy Farmers 2. Daily wage Labourers 3. Cashew farmers 4. Mango Farmers 5. Cotton and Vegetable Farmers | I4: Caste Composition | J4: 1.YCP has the majority of the vote bank from Mala and Kondareddy and a slight edge from the Kapu vote bank due to local Leadership. 2.TDP has consolidated the majority vote bank from the Kapu and BC communities (Yadava). | K4: YCP>TDP>JSP | L4: The corruption of the YSRCP, the lack of public housing, and the poor condition of the roads under YSRCP government are all being vigorously fought against by the TDP. | M4: Strong | N4: Strong Cadre and Strong Leadership | O4: Strong | P4: Strong Cadre and Strong Leadership | Q4: Weak | R4: Weak Leadership & Weak Cadre | S4: Positive | T4: Positive Image Welfare Schemes | W4: Review | Y4: Prashanth
